Workbook

Sheet Итоги
A1: «Компас» — финансовая модель на 24 месяца
A2: Октябрь 2026 — сентябрь 2028. One — 990 ₽ в месяц, Pro — 49 900 ₽ в год, два новых договора Pro в месяц. ООО на АУСН.
A4: Главное
A5: Месяц выхода в прибыль | B5: ='Экономика клиента'!B25 -> 24 | C5: Первый месяц с чистой прибылью.
A6: Месяц, когда кончаются стартовые деньги | B6: =IFERROR(MATCH(TRUE(),INDEX('По месяцам'!$B$47:$Y$47<0,0),0),"не кончаются") -> 13
A7: Сколько денег нужно сверх стартовых | B7: =MAX(0,-MIN('По месяцам'!B47:Y47)) -> 486209.61 | C7: Самая глубокая точка минуса.
A8: За два года
A9: Платящих One через 12 месяцев | B9: ='По месяцам'!M10 -> 37.702391
A10: Платящих One через 24 месяца | B10: ='По месяцам'!Y10 -> 96.019842
A11: Договоров Pro через 24 месяца | B11: ='По месяцам'!Y13 -> 35.686478
A12: Выручка за 24 месяца | B12: =SUM('По месяцам'!B17:Y17) -> 2691410.4
A13: из неё от Pro | B13: =SUM('По месяцам'!B16:Y16) -> 1723620.1
A14: Расходы за 24 месяца | B14: =SUM('По месяцам'!B38:Y38) -> 4180769.8
A15: Налоги за 24 месяца | B15: =SUM('По месяцам'!B43:Y43) -> 80742.311
A16: Чистая прибыль за 24 месяца | B16: =SUM('По месяцам'!B45:Y45) -> -1570101.7
A17: Один клиент
A18: Вклад одного подписчика One в месяц | B18: ='Экономика клиента'!B9 -> 907.84365
A19: Вклад одного договора Pro в месяц | B19: ='Экономика клиента'!B17 -> 3758.3333
A20: Один Pro = столько подписчиков One | B20: ='Экономика клиента'!B18 -> 4.1
A21: LTV ÷ CAC | B21: ='Экономика клиента'!B12 -> 0.79436319 | C21: Ниже 1 — реклама не окупается.
A22: Порог: подписчиков One без Pro | B22: ='Экономика клиента'!B21 -> 111 | C22: Без разработчика.
A23: Порог: договоров Pro без One | B23: ='Экономика клиента'!B22 -> 27 | C23: Без разработчика.
A25: Как читать
A26: • | B26: Меняйте только жёлтые клетки на листе «Допущения» — всё остальное пересчитается.
A27: • | B27: Результат решают три числа: отток подписчиков, темп договоров Pro и зарплата разработчика. Все три — на листе «Допущения».
A28: • | B28: Числа с пометкой «уточнить» — оценки, а не счета. Их стоит заменить в первую очередь.
A29: • | B29: Лист «Налоги и риски» стоит прочитать целиком: там то, что не видно в числах.

Sheet Экономика клиента
A1: Экономика одного клиента
A2: Здесь нет роста — только один подписчик или один договор и деньги вокруг него. Если здесь не сходится, рост не поможет.
A4: Подписчик One
A5: Средний платёж в месяц | B5: =Допущения!$B$6*(1-Допущения!$B$8)+Допущения!$B$7/12*Допущения!$B$8 -> 953.7 | C5: Помесячные и годовые вперемешку; годовая засчитывается по 1/12 в месяц.
A6: минус комиссия за платёж | B6: =-$B$5*Допущения!$B$54 -> -28.611
A7: минус возвраты | B7: =-$B$5*Допущения!$B$8*Допущения!$B$10/2 -> -5.24535 | C7: Только с годовых подписок и только за неиспользованный срок.
A8: минус ассистент | B8: =-Допущения!$B$26*Допущения!$B$27 -> -12 | C8: Включённые вопросы × измеренная цена вопроса.
A9: ВКЛАД ОДНОГО ПОДПИСЧИКА В МЕСЯЦ | B9: =$B$5+$B$6+$B$7+$B$8 -> 907.84365 | C9: Столько он приносит на покрытие постоянных расходов.
A10: Принесёт за всю жизнь подписки (LTV) | B10: =$B$9/Допущения!$B$9 -> 9078.4365 | C10: Вклад в месяц, делённый на отток.
A11: Стоит привести одного платящего через рекламу (CAC) | B11: =Допущения!$B$16/Допущения!$B$17 -> 11428.571 | C11: Цена регистрации, делённая на долю тех, кто начинает платить.
A12: LTV ÷ CAC | B12: =$B$10/$B$11 -> 0.79436319 | C12: Ниже 1 — реклама сжигает деньги: подписчик приносит меньше, чем стоил. У здоровой подписки 3 и выше.
A13: Цена регистрации, при которой реклама окупается втрое | B13: =$B$10*Допущения!$B$17/3 -> 211.83019 | C13: Задача маркетингу одним числом: приводить людей дешевле этого.
A14: Договор Pro
A15: Платит в месяц | B15: =Допущения!$B$20/12 -> 4158.3333 | C15: Годовой договор, разложенный на месяцы. Деньгами приходит сразу за год.
A16: минус обслуживание | B16: =-Допущения!$B$24 -> -400
A17: ВКЛАД ОДНОГО ДОГОВОРА В МЕСЯЦ | B17: =$B$15+$B$16 -> 3758.3333
A18: Один Pro = столько подписчиков One | B18: =ROUND($B$17/$B$9,1) -> 4.1 | C18: Pro здесь не рычаг, а второй ручеёк той же ширины: чтобы он решал, нужен поток договоров, а не пара крупных клиентов.
A19: Порог безубыточности
A20: Постоянные расходы в месяц | B20: =Допущения!$B$29+Допущения!$B$30+Допущения!$B$31+Допущения!$B$32+Допущения!$B$34+Допущения!$B$35+Допущения!$B$36+Допущения!$B$37+Допущения!$B$39+Допущения!$B$38+Допущения!$B$41+Допущения!$B$42+Допущения!$B$52/12 -> 99954.583 | C20: Всё, что платится независимо от числа клиентов, без разработчика.
A21: Нужно подписчиков One, если нет Pro | B21: =ROUNDUP($B$20/$B$9,0) -> 111
A22: Нужно договоров Pro, если нет One | B22: =ROUNDUP($B$20/$B$17,0) -> 27 | C22: Любая настоящая смесь лежит между этими двумя числами.
A23: подписчиков One с разработчиком за 50 тыс ₽ | B23: =ROUNDUP(($B$20+Допущения!$B$44)/$B$9,0) -> 166
A24: подписчиков One с разработчиком за 100 тыс ₽ | B24: =ROUNDUP(($B$20+Допущения!$B$46)/$B$9,0) -> 221 | C24: Разница с первой строкой — цена разработчика, выраженная в подписчиках.
A25: Месяц выхода в прибыль | B25: =IFERROR(MATCH(TRUE(),INDEX('По месяцам'!$B$45:$Y$45>0,0),0),"за 24 месяца не выходим") -> 24 | C25: Первый месяц с чистой прибылью, из помесячного расчёта.

Sheet Допущения
A1: Допущения модели
A2: Жёлтые клетки можно менять — всё остальное в книге считается от них.
A3: «Ваш счёт» и «ваше решение» — названо вами. «Уточнить» — моя оценка, её надо заменить фактом.
A5: Тариф One — для человека
A6: One, ₽ в месяц | B6: 990 | C6: Ваше решение.
A7: One, ₽ в год | B7: 9900 | C7: Десять месяцев по цене двенадцати. Годовая оплата ценна тем, что даёт деньги вперёд.
A8: Доля годовых подписок к 24-му месяцу | B8: 0.22 | C8: Растёт от нуля: сначала люди платят помесячно, пока не убедились.
A9: Отток в месяц | B9: 0.1 | C9: Сколько платящих уходит каждый месяц. 10% — это около 10 месяцев жизни подписки. Не измерено: проверять с третьего месяца продаж. Самое важное число модели.
A10: Доля годовых подписок, по которым просят возврат | B10: 0.05 | C10: Человек вправе отказаться в любой момент и вернуть деньги за неиспользованный срок (ст. 32 закона о защите прав потребителей). С помесячной подписки возвращать нечего, поэтому считаются только годовые: доля отказов × половина срока.
A11: Откуда берутся подписчики
A12: Сколько человек в России вообще может это купить | B12: 25000 | C12: Ядро ≈3 400: сотрудники 286 консультантов из нашей же базы (по 5 человек), корпоративное развитие 700 покупателей (по 2), фонды и оценщики. Остальное — аналитики, журналисты, преподаватели, студенты, частные инвесторы. Самое зыбкое число модели.
A13: Какая доля из них может платить | B13: 0.035 | C13: Верхняя граница: больше платящих, чем столько, модель не допускает.
A14: Бесплатных регистраций в месяц на старте | B14: 25 | C14: Факт закрытого теста — 16 аккаунтов за 7 недель, по заявке и без продвижения. Без двери на входе берём 25.
A15: Рост бесплатных регистраций в месяц | B15: 0.1 | C15: Канал, пересылки, поиск. Рост замедляется по мере того, как рынок заполняется.
A16: Цена одной регистрации из рекламы, ₽ | B16: 800 | C16: Посев в отраслевом канале: 10–50 тыс ₽ за размещение, 20–60 регистраций. Измерить первым же посевом.
A17: Доля зарегистрировавшихся, которые начинают платить | B17: 0.07 | C17: Не измерено. Для бесплатной регистрации с платной подпиской обычно 3–10%.
A18: Через сколько месяцев после регистрации начинают платить | B18: 2 | C18: Человек смотрит, возвращается, ждёт повода.
A19: Тариф Pro — для команды
A20: Pro, ₽ в год | B20: 49900 | C20: Ваше решение. Рядом на рынке: Контур.Фокус базовый — от 31 тыс ₽ в год, Seldon.Basis — от 54 тыс, СПАРК «Корпоратив» — около 200 тыс.
A21: Новых Pro в месяц | B21: 2 | C21: Один договор в две недели. Продаж Pro ещё не было — число проверяется первыми разговорами с клиентами, а не расчётом.
A22: Месяц, когда приходит первый Pro | B22: 4 | C22: Раньше не получится: нужны оферта для юрлиц, счёт и акты.
A23: Доля Pro, которые не продлевают договор через год | B23: 0.2 | C23: Каждый пятый.
A24: Обслуживание одного Pro, ₽ в месяц | B24: 400 | C24: Ассистент для команды из трёх человек (60 вопросов по 1 ₽), выгрузки, ответы на вопросы.
A25: Ассистент на сайте
A26: Вопросов в месяц, включённых в One | B26: 12 | C26: Ограничение нужно не ради экономии, а чтобы один человек или скрипт не задал тысячу вопросов за счёт остальных.
A27: Цена одного вопроса, ₽ | B27: 1 | C27: Измерено на 50 вопросах из живой базы: в среднем 1,04 ₽ (обычный вопрос 0,80–1,12 ₽, с поиском в интернете 1,19–1,67 ₽).
A28: Постоянные расходы, ₽ в месяц — ваши счета
A29: Хостинг Timeweb | B29: 5300 | C29: Ваш счёт. Сервер сайта и база.
A30: Yandex.Cloud | B30: 7000 | C30: Ваш счёт. Облако и ассистент при нынешнем числе пользователей; рост вместе с подписчиками считается отдельно.
A31: Claude | B31: 20000 | C31: Ваш счёт. Инструмент разработки. Ассистент на сайте работает на модели Яндекса, его расход — в строке выше.
A32: Аренда офиса | B32: 1908 | C32: Ваш счёт: 22 900 ₽ в год.
A33: Постоянные расходы, ₽ в месяц — оценки, уточнить
A34: API-ФНС | B34: 8000 | C34: Финансы компаний. Уточнить по счёту.
A35: Онлайн-касса | B35: 2500 | C35: При оплате от человека нужен чек. Обычно его выбивает платёжный сервис — уточнить в договоре.
A36: Бухгалтерия | B36: 7000 | C36: На АУСН учёт простой: налог считает налоговая по выписке банка. Уточнить у бухгалтера.
A37: Юрист и патентный поверенный | B37: 10000 | C37: Товарный знак, оферта, политика персональных данных. Уточнить.
A38: Платная реклама | B38: 30000 | C38: Небольшой бюджет, чтобы измерить цену регистрации. При нынешних допущениях реклама себя не окупает (см. «Экономика клиента»).
A39: Прочее | B39: 8000 | C39: Связь, сервисы, банк. Уточнить.
A40: Команда
A41: Зарплата гендиректора, ₽ в месяц | B41: 0 | C41: Ваше решение: не платим. Взносов за гендиректора на АУСН нет в любом случае.
...

Sheet По месяцам
A1: Расчёт по месяцам
A2: Каждая клетка — формула от листа «Допущения».
A3: Месяц | B3: окт 2026 | C3: ноя 2026 | D3: дек 2026 | E3: янв 2027 | F3: фев 2027 | G3: мар 2027 | H3: апр 2027 | I3: май 2027 | J3: июн 2027 | K3: июл 2027 | L3: авг 2027 | M3: сен 2027 | N3: окт 2027 | O3: ноя 2027 | P3: дек 2027 | Q3: янв 2028 | R3: фев 2028 | S3: мар 2028 | T3: апр 2028 | U3: май 2028 | V3: июн 2028 | W3: июл 2028 | X3: авг 2028 | Y3: сен 2028
A4: Регистрации и подписчики One
A5: Бесплатных регистраций | B5: =Допущения!$B$14*(1+Допущения!$B$15)^0 -> 25 | C5: =Допущения!$B$14*(1+Допущения!$B$15)^1 -> 27.5 | D5: =Допущения!$B$14*(1+Допущения!$B$15)^2 -> 30.25 | E5: =Допущения!$B$14*(1+Допущения!$B$15)^3 -> 33.275 | F5: =Допущения!$B$14*(1+Допущения!$B$15)^4 -> 36.6025 | G5: =Допущения!$B$14*(1+Допущения!$B$15)^5 -> 40.26275 | H5: =Допущения!$B$14*(1+Допущения!$B$15)^6 -> 44.289025 | I5: =Допущения!$B$14*(1+Допущения!$B$15)^7 -> 48.717928 | J5: =Допущения!$B$14*(1+Допущения!$B$15)^8 -> 53.58972 | K5: =Допущения!$B$14*(1+Допущения!$B$15)^9 -> 58.948692 | L5: =Допущения!$B$14*(1+Допущения!$B$15)^10 -> 64.843562 | M5: =Допущения!$B$14*(1+Допущения!$B$15)^11 -> 71.327918 | N5: =Допущения!$B$14*(1+Допущения!$B$15)^12 -> 78.460709 | O5: =Допущения!$B$14*(1+Допущения!$B$15)^13 -> 86.30678 | P5: =Допущения!$B$14*(1+Допущения!$B$15)^14 -> 94.937458 | Q5: =Допущения!$B$14*(1+Допущения!$B$15)^15 -> 104.4312 | R5: =Допущения!$B$14*(1+Допущения!$B$15)^16 -> 114.87432 | S5: =Допущения!$B$14*(1+Допущения!$B$15)^17 -> 126.36176 | T5: =Допущения!$B$14*(1+Допущения!$B$15)^18 -> 138.99793 | U5: =Допущения!$B$14*(1+Допущения!$B$15)^19 -> 152.89773 | V5: =Допущения!$B$14*(1+Допущения!$B$15)^20 -> 168.1875 | W5: =Допущения!$B$14*(1+Допущения!$B$15)^21 -> 185.00625 | X5: =Допущения!$B$14*(1+Допущения!$B$15)^22 -> 203.50687 | Y5: =Допущения!$B$14*(1+Допущения!$B$15)^23 -> 223.85756
A6: Регистраций из рекламы | B6: =Допущения!$B$38/Допущения!$B$16 -> 37.5 | C6: =Допущения!$B$38/Допущения!$B$16 -> 37.5 | D6: =Допущения!$B$38/Допущения!$B$16 -> 37.5 | E6: =Допущения!$B$38/Допущения!$B$16 -> 37.5 | F6: =Допущения!$B$38/Допущения!$B$16 -> 37.5 | G6: =Допущения!$B$38/Допущения!$B$16 -> 37.5 | H6: =Допущения!$B$38/Допущения!$B$16 -> 37.5 | I6: =Допущения!$B$38/Допущения!$B$16 -> 37.5 | ... Y6: =Допущения!$B$38/Допущения!$B$16 -> 37.5 | Z6: Бюджет рекламы, делённый на цену регистрации.
A7: Регистраций за месяц | B7: =ROUND((B5+B6)*1,0) -> 63 | C7: =ROUND((C5+C6)*MAX(0,1-B8/Допущения!$B$12),0) -> 65 | D7: =ROUND((D5+D6)*MAX(0,1-C8/Допущения!$B$12),0) -> 67 | E7: =ROUND((E5+E6)*MAX(0,1-D8/Допущения!$B$12),0) -> 70 | F7: =ROUND((F5+F6)*MAX(0,1-E8/Допущения!$B$12),0) -> 73 | G7: =ROUND((G5+G6)*MAX(0,1-F8/Допущения!$B$12),0) -> 77 | H7: =ROUND((H5+H6)*MAX(0,1-G8/Допущения!$B$12),0) -> 80 | I7: =ROUND((I5+I6)*MAX(0,1-H8/Допущения!$B$12),0) -> 85 | J7: =ROUND((J5+J6)*MAX(0,1-I8/Допущения!$B$12),0) -> 89 | ... Y7: =ROUND((Y5+Y6)*MAX(0,1-X8/Допущения!$B$12),0) -> 233 | Z7: Рост замедляется по мере заполнения рынка: множитель «какая доля ещё не зарегистрирована».
A8: Зарегистрировано всего | B8: =B7 -> 63 | C8: =B8+C7 -> 128 | D8: =C8+D7 -> 195 | E8: =D8+E7 -> 265 | F8: =E8+F7 -> 338 | G8: =F8+G7 -> 415 | H8: =G8+H7 -> 495 | I8: =H8+I7 -> 580 | J8: =I8+J7 -> 669 | ... Y8: =X8+Y7 -> 2933
A9: Новых платящих | B9: =IF(COLUMN()-1-Допущения!$B$18<1,0,IFERROR(ROUND(INDEX($B$7:$Y$7,1,COLUMN()-1-Допущения!$B$18)*Допущения!$B$17,0),0)) -> 0 | C9: =IF(COLUMN()-1-Допущения!$B$18<1,0,IFERROR(ROUND(INDEX($B$7:$Y$7,1,COLUMN()-1-Допущения!$B$18)*Допущения!$B$17,0),0)) -> 0 | D9: =IF(COLUMN()-1-Допущения!$B$18<1,0,IFERROR(ROUND(INDEX($B$7:$Y$7,1,COLUMN()-1-Допущения!$B$18)*Допущения!$B$17,0),0)) -> 4 | E9: =IF(COLUMN()-1-Допущения!$B$18<1,0,IFERROR(ROUND(INDEX($B$7:$Y$7,1,COLUMN()-1-Допущения!$B$18)*Допущения!$B$17,0),0)) -> 5 | F9: =IF(COLUMN()-1-Допущения!$B$18<1,0,IFERROR(ROUND(INDEX($B$7:$Y$7,1,COLUMN()-1-Допущения!$B$18)*Допущения!$B$17,0),0)) -> 5 | G9: =IF(COLUMN()-1-Допущения!$B$18<1,0,IFERROR(ROUND(INDEX($B$7:$Y$7,1,COLUMN()-1-Допущения!$B$18)*Допущения!$B$17,0),0)) -> 5 | H9: =IF(COLUMN()-1-Допущения!$B$18<1,0,IFERROR(ROUND(INDEX($B$7:$Y$7,1,COLUMN()-1-Допущения!$B$18)*Допущения!$B$17,0),0)) -> 5 | I9: =IF(COLUMN()-1-Допущения!$B$18<1,0,IFERROR(ROUND(INDEX($B$7:$Y$7,1,COLUMN()-1-Допущения!$B$18)*Допущения!$B$17,0),0)) -> 5 | ... Y9: =IF(COLUMN()-1-Допущения!$B$18<1,0,IFERROR(ROUND(INDEX($B$7:$Y$7,1,COLUMN()-1-Допущения!$B$18)*Допущения!$B$17,0),0)) -> 14 | Z9: Регистрация превращается в оплату с задержкой из допущений.
A10: Платящих на конец месяца | B10: =MIN(Допущения!$B$57+B9,Допущения!$B$12*Допущения!$B$13) -> 0 | C10: =MIN(B10*(1-Допущения!$B$9*(1-Допущения!$B$8*1/24))+C9,Допущения!$B$12*Допущения!$B$13) -> 0 | D10: =MIN(C10*(1-Допущения!$B$9*(1-Допущения!$B$8*2/24))+D9,Допущения!$B$12*Допущения!$B$13) -> 4 | E10: =MIN(D10*(1-Допущения!$B$9*(1-Допущения!$B$8*3/24))+E9,Допущения!$B$12*Допущения!$B$13) -> 8.611 | F10: =MIN(E10*(1-Допущения!$B$9*(1-Допущения!$B$8*4/24))+F9,Допущения!$B$12*Допущения!$B$13) -> 12.781474 | G10: =MIN(F10*(1-Допущения!$B$9*(1-Допущения!$B$8*5/24))+G9,Допущения!$B$12*Допущения!$B$13) -> 16.561908 | H10: =MIN(G10*(1-Допущения!$B$9*(1-Допущения!$B$8*6/24))+H9,Допущения!$B$12*Допущения!$B$13) -> 19.996808 | I10: =MIN(H10*(1-Допущения!$B$9*(1-Допущения!$B$8*7/24))+I9,Допущения!$B$12*Допущения!$B$13) -> 23.12544 | J10: =MIN(I10*(1-Допущения!$B$9*(1-Допущения!$B$8*8/24))+J9,Допущения!$B$12*Допущения!$B$13) -> 26.982482 | K10: =MIN(J10*(1-Допущения!$B$9*(1-Допущения!$B$8*9/24))+K9,Допущения!$B$12*Допущения!$B$13) -> 30.50684 | L10: =MIN(K10*(1-Допущения!$B$9*(1-Допущения!$B$8*10/24))+L9,Допущения!$B$12*Допущения!$B$13) -> 33.735802 | M10: =MIN(L10*(1-Допущения!$B$9*(1-Допущения!$B$8*11/24))+M9,Допущения!$B$12*Допущения!$B$13) -> 37.702391 | N10: =MIN(M10*(1-Допущения!$B$9*(1-Допущения!$B$8*12/24))+N9,Допущения!$B$12*Допущения!$B$13) -> 41.346878 | O10: =MIN(N10*(1-Допущения!$B$9*(1-Допущения!$B$8*13/24))+O9,Допущения!$B$12*Допущения!$B$13) -> 44.704907 | P10: =MIN(O10*(1-Допущения!$B$9*(1-Допущения!$B$8*14/24))+P9,Допущения!$B$12*Допущения!$B$13) -> 48.808129 | Q10: =MIN(P10*(1-Допущения!$B$9*(1-Допущения!$B$8*15/24))+Q9,Допущения!$B$12*Допущения!$B$13) -> 52.598428 | R10: =MIN(Q10*(1-Допущения!$B$9*(1-Допущения!$B$8*16/24))+R9,Допущения!$B$12*Допущения!$B$13) -> 57.110029 | S10: =MIN(R10*(1-Допущения!$B$9*(1-Допущения!$B$8*17/24))+S9,Допущения!$B$12*Допущения!$B$13) -> 61.288991 | T10: =MIN(S10*(1-Допущения!$B$9*(1-Допущения!$B$8*18/24))+T9,Допущения!$B$12*Допущения!$B$13) -> 66.17136 | U10: =MIN(T10*(1-Допущения!$B$9*(1-Допущения!$B$8*19/24))+U9,Допущения!$B$12*Допущения!$B$13) -> 71.706709 | V10: =MIN(U10*(1-Допущения!$B$9*(1-Допущения!$B$8*20/24))+V9,Допущения!$B$12*Допущения!$B$13) -> 76.850661 | W10: =MIN(V10*(1-Допущения!$B$9*(1-Допущения!$B$8*21/24))+W9,Допущения!$B$12*Допущения!$B$13) -> 82.64497 | X10: =MIN(W10*(1-Допущения!$B$9*(1-Допущения!$B$8*22/24))+X9,Допущения!$B$12*Допущения!$B$13) -> 89.047146 | Y10: =MIN(X10*(1-Допущения!$B$9*(1-Допущения!$B$8*23/24))+Y9,Допущения!$B$12*Допущения!$B$13) -> 96.019842 | Z10: Годовые подписки не уходят помесячно: их доля растёт и гасит отток.
A11: Договоры Pro
A12: Новых Pro | B12: =IF(1<Допущения!$B$22,0,Допущения!$B$21) -> 0 | C12: =IF(2<Допущения!$B$22,0,Допущения!$B$21) -> 0 | D12: =IF(3<Допущения!$B$22,0,Допущения!$B$21) -> 0 | E12: =IF(4<Допущения!$B$22,0,Допущения!$B$21) -> 2 | F12: =IF(5<Допущения!$B$22,0,Допущения!$B$21) -> 2 | G12: =IF(6<Допущения!$B$22,0,Допущения!$B$21) -> 2 | H12: =IF(7<Допущения!$B$22,0,Допущения!$B$21) -> 2 | I12: =IF(8<Допущения!$B$22,0,Допущения!$B$21) -> 2 | J12: =IF(9<Допущения!$B$22,0,Допущения!$B$21) -> 2 | K12: =IF(10<Допущения!$B$22,0,Допущения!$B$21) -> 2 | L12: =IF(11<Допущения!$B$22,0,Допущения!$B$21) -> 2 | M12: =IF(12<Допущения!$B$22,0,Допущения!$B$21) -> 2 | N12: =IF(13<Допущения!$B$22,0,Допущения!$B$21) -> 2 | O12: =IF(14<Допущения!$B$22,0,Допущения!$B$21) -> 2 | P12: =IF(15<Допущения!$B$22,0,Допущения!$B$21) -> 2 | Q12: =IF(16<Допущения!$B$22,0,Допущения!$B$21) -> 2 | R12: =IF(17<Допущения!$B$22,0,Допущения!$B$21) -> 2 | S12: =IF(18<Допущения!$B$22,0,Допущения!$B$21) -> 2 | T12: =IF(19<Допущения!$B$22,0,Допущения!$B$21) -> 2 | U12: =IF(20<Допущения!$B$22,0,Допущения!$B$21) -> 2 | V12: =IF(21<Допущения!$B$22,0,Допущения!$B$21) -> 2 | W12: =IF(22<Допущения!$B$22,0,Допущения!$B$21) -> 2 | X12: =IF(23<Допущения!$B$22,0,Допущения!$B$21) -> 2 | Y12: =IF(24<Допущения!$B$22,0,Допущения!$B$21) -> 2
A13: Pro на конец месяца | B13: =B12 -> 0 | C13: =B13*(1-Допущения!$B$23/12)+C12 -> 0 | D13: =C13*(1-Допущения!$B$23/12)+D12 -> 0 | E13: =D13*(1-Допущения!$B$23/12)+E12 -> 2 | F13: =E13*(1-Допущения!$B$23/12)+F12 -> 3.9666667 | G13: =F13*(1-Допущения!$B$23/12)+G12 -> 5.9005556 | H13: =G13*(1-Допущения!$B$23/12)+H12 -> 7.802213 | I13: =H13*(1-Допущения!$B$23/12)+I12 -> 9.6721761 | J13: =I13*(1-Допущения!$B$23/12)+J12 -> 11.510973 | ... Y13: =X13*(1-Допущения!$B$23/12)+Y12 -> 35.686478 | Z13: Дробь — это средний поток: за год не продлевает пятая часть.
A14: Выручка
A15: Выручка от One | B15: =B10*(Допущения!$B$6*(1-Допущения!$B$8*0/24)+Допущения!$B$7/12*Допущения!$B$8*0/24) -> 0 | C15: =C10*(Допущения!$B$6*(1-Допущения!$B$8*1/24)+Допущения!$B$7/12*Допущения!$B$8*1/24) -> 0 | D15: =D10*(Допущения!$B$6*(1-Допущения!$B$8*2/24)+Допущения!$B$7/12*Допущения!$B$8*2/24) -> 3947.9 | E15: =E10*(Допущения!$B$6*(1-Допущения!$B$8*3/24)+Допущения!$B$7/12*Допущения!$B$8*3/24) -> 8485.8176 | F15: =F10*(Допущения!$B$6*(1-Допущения!$B$8*4/24)+Допущения!$B$7/12*Допущения!$B$8*4/24) -> 12576.331 | G15: =G10*(Допущения!$B$6*(1-Допущения!$B$8*5/24)+Допущения!$B$7/12*Допущения!$B$8*5/24) -> 16271.04 | H15: =H10*(Допущения!$B$6*(1-Допущения!$B$8*6/24)+Допущения!$B$7/12*Допущения!$B$8*6/24) -> 19615.369 | I15: =I10*(Допущения!$B$6*(1-Допущения!$B$8*7/24)+Допущения!$B$7/12*Допущения!$B$8*7/24) -> 22649.345 | J15: =J10*(Допущения!$B$6*(1-Допущения!$B$8*8/24)+Допущения!$B$7/12*Допущения!$B$8*8/24) -> 26386.17 | K15: =K10*(Допущения!$B$6*(1-Допущения!$B$8*9/24)+Допущения!$B$7/12*Допущения!$B$8*9/24) -> 29786.497 | L15: =L10*(Допущения!$B$6*(1-Допущения!$B$8*10/24)+Допущения!$B$7/12*Допущения!$B$8*10/24) -> 32888.19 | M15: =M10*(Допущения!$B$6*(1-Допущения!$B$8*11/24)+Допущения!$B$7/12*Допущения!$B$8*11/24) -> 36698.093 | N15: =N10*(Допущения!$B$6*(1-Допущения!$B$8*12/24)+Допущения!$B$7/12*Допущения!$B$8*12/24) -> 40182.963 | O15: =O10*(Допущения!$B$6*(1-Допущения!$B$8*13/24)+Допущения!$B$7/12*Допущения!$B$8*13/24) -> 43378.848 | P15: =P10*(Допущения!$B$6*(1-Допущения!$B$8*14/24)+Допущения!$B$7/12*Допущения!$B$8*14/24) -> 47286.536 | Q15: =Q10*(Допущения!$B$6*(1-Допущения!$B$8*15/24)+Допущения!$B$7/12*Допущения!$B$8*15/24) -> 50879.117 | R15: =R10*(Допущения!$B$6*(1-Допущения!$B$8*16/24)+Допущения!$B$7/12*Допущения!$B$8*16/24) -> 55156.866 | S15: =S10*(Допущения!$B$6*(1-Допущения!$B$8*17/24)+Допущения!$B$7/12*Допущения!$B$8*17/24) -> 59100.208 | T15: =T10*(Допущения!$B$6*(1-Допущения!$B$8*18/24)+Допущения!$B$7/12*Допущения!$B$8*18/24) -> 63708.131 | U15: =U10*(Допущения!$B$6*(1-Допущения!$B$8*19/24)+Допущения!$B$7/12*Допущения!$B$8*19/24) -> 68928.97 | V15: =V10*(Допущения!$B$6*(1-Допущения!$B$8*20/24)+Допущения!$B$7/12*Допущения!$B$8*20/24) -> 73757.422 | W15: =W10*(Допущения!$B$6*(1-Допущения!$B$8*21/24)+Допущения!$B$7/12*Допущения!$B$8*21/24) -> 79193.509 | X15: =X10*(Допущения!$B$6*(1-Допущения!$B$8*22/24)+Допущения!$B$7/12*Допущения!$B$8*22/24) -> 85193.631 | Y15: =Y10*(Допущения!$B$6*(1-Допущения!$B$8*23/24)+Допущения!$B$7/12*Допущения!$B$8*23/24) -> 91719.354 | Z15: Годовая подписка засчитывается по 1/12 в месяц.
A16: Выручка от Pro | B16: =B13*Допущения!$B$20/12 -> 0 | C16: =C13*Допущения!$B$20/12 -> 0 | D16: =D13*Допущения!$B$20/12 -> 0 | E16: =E13*Допущения!$B$20/12 -> 8316.6667 | F16: =F13*Допущения!$B$20/12 -> 16494.722 | G16: =G13*Допущения!$B$20/12 -> 24536.477 | H16: =H13*Допущения!$B$20/12 -> 32444.202 | I16: =I13*Допущения!$B$20/12 -> 40220.132 | ... Y16: =Y13*Допущения!$B$20/12 -> 148396.27 | Z16: Годовой договор засчитывается по 1/12 в месяц.
A17: Выручка всего | B17: =B15+B16 -> 0 | C17: =C15+C16 -> 0 | D17: =D15+D16 -> 3947.9 | E17: =E15+E16 -> 16802.484 | F17: =F15+F16 -> 29071.053 | G17: =G15+G16 -> 40807.516 | H17: =H15+H16 -> 52059.571 | I17: =I15+I16 -> 62869.477 | ... Y17: =Y15+Y16 -> 240115.62
A18: из неё годовых подписок One продано, ₽ | B18: =B9*Допущения!$B$8*0/24*Допущения!$B$7 -> 0 | C18: =C9*Допущения!$B$8*1/24*Допущения!$B$7 -> 0 | D18: =D9*Допущения!$B$8*2/24*Допущения!$B$7 -> 726 | E18: =E9*Допущения!$B$8*3/24*Допущения!$B$7 -> 1361.25 | F18: =F9*Допущения!$B$8*4/24*Допущения!$B$7 -> 1815 | G18: =G9*Допущения!$B$8*5/24*Допущения!$B$7 -> 2268.75 | H18: =H9*Допущения!$B$8*6/24*Допущения!$B$7 -> 2722.5 | I18: =I9*Допущения!$B$8*7/24*Допущения!$B$7 -> 3176.25 | J18: =J9*Допущения!$B$8*8/24*Допущения!$B$7 -> 4356 | K18: =K9*Допущения!$B$8*9/24*Допущения!$B$7 -> 4900.5 | L18: =L9*Допущения!$B$8*10/24*Допущения!$B$7 -> 5445 | M18: =M9*Допущения!$B$8*11/24*Допущения!$B$7 -> 6987.75 | N18: =N9*Допущения!$B$8*12/24*Допущения!$B$7 -> 7623 | O18: =O9*Допущения!$B$8*13/24*Допущения!$B$7 -> 8258.25 | P18: =P9*Допущения!$B$8*14/24*Допущения!$B$7 -> 10164 | Q18: =Q9*Допущения!$B$8*15/24*Допущения!$B$7 -> 10890 | R18: =R9*Допущения!$B$8*16/24*Допущения!$B$7 -> 13068 | S18: =S9*Допущения!$B$8*17/24*Допущения!$B$7 -> 13884.75 | T18: =T9*Допущения!$B$8*18/24*Допущения!$B$7 -> 16335 | U18: =U9*Допущения!$B$8*19/24*Допущения!$B$7 -> 18966.75 | V18: =V9*Допущения!$B$8*20/24*Допущения!$B$7 -> 19965 | W18: =W9*Допущения!$B$8*21/24*Допущения!$B$7 -> 22869 | X18: =X9*Допущения!$B$8*22/24*Допущения!$B$7 -> 25954.5 | Y18: =Y9*Допущения!$B$8*23/24*Допущения!$B$7 -> 29221.5 | Z18: Деньги за год вперёд. Только с них возможен возврат.
A19: Поступило денег | B19: =B15+B18-B9*Допущения!$B$8*0/24*Допущения!$B$7/12+B12*Допущения!$B$20 -> 0 | C19: =C15+C18-C9*Допущения!$B$8*1/24*Допущения!$B$7/12+C12*Допущения!$B$20 -> 0 | D19: =D15+D18-D9*Допущения!$B$8*2/24*Допущения!$B$7/12+D12*Допущения!$B$20 -> 4613.4 | E19: =E15+E18-E9*Допущения!$B$8*3/24*Допущения!$B$7/12+E12*Допущения!$B$20 -> 109533.63 | F19: =F15+F18-F9*Допущения!$B$8*4/24*Допущения!$B$7/12+F12*Допущения!$B$20 -> 114040.08 | G19: =G15+G18-G9*Допущения!$B$8*5/24*Допущения!$B$7/12+G12*Допущения!$B$20 -> 118150.73 | H19: =H15+H18-H9*Допущения!$B$8*6/24*Допущения!$B$7/12+H12*Допущения!$B$20 -> 121910.99 | I19: =I15+I18-I9*Допущения!$B$8*7/24*Допущения!$B$7/12+I12*Допущения!$B$20 -> 125360.91 | J19: =J15+J18-J9*Допущения!$B$8*8/24*Допущения!$B$7/12+J12*Допущения!$B$20 -> 130179.17 | K19: =K15+K18-K9*Допущения!$B$8*9/24*Допущения!$B$7/12+K12*Допущения!$B$20 -> 134078.62 | L19: =L15+L18-L9*Допущения!$B$8*10/24*Допущения!$B$7/12+L12*Допущения!$B$20 -> 137679.44 | M19: =M15+M18-M9*Допущения!$B$8*11/24*Допущения!$B$7/12+M12*Допущения!$B$20 -> 142903.53 | N19: =N15+N18-N9*Допущения!$B$8*12/24*Допущения!$B$7/12+N12*Допущения!$B$20 -> 146970.71 | O19: =O15+O18-O9*Допущения!$B$8*13/24*Допущения!$B$7/12+O12*Допущения!$B$20 -> 150748.91 | P19: =P15+P18-P9*Допущения!$B$8*14/24*Допущения!$B$7/12+P12*Допущения!$B$20 -> 156403.54 | Q19: =Q15+Q18-Q9*Допущения!$B$8*15/24*Допущения!$B$7/12+Q12*Допущения!$B$20 -> 160661.62 | R19: =R15+R18-R9*Допущения!$B$8*16/24*Допущения!$B$7/12+R12*Допущения!$B$20 -> 166935.87 | S19: =S15+S18-S9*Допущения!$B$8*17/24*Допущения!$B$7/12+S12*Допущения!$B$20 -> 171627.9 | T19: =T15+T18-T9*Допущения!$B$8*18/24*Допущения!$B$7/12+T12*Допущения!$B$20 -> 178481.88 | U19: =U15+U18-U9*Допущения!$B$8*19/24*Допущения!$B$7/12+U12*Допущения!$B$20 -> 186115.16 | V19: =V15+V18-V9*Допущения!$B$8*20/24*Допущения!$B$7/12+V12*Допущения!$B$20 -> 191858.67 | W19: =W15+W18-W9*Допущения!$B$8*21/24*Допущения!$B$7/12+W12*Допущения!$B$20 -> 199956.76 | X19: =X15+X18-X9*Допущения!$B$8*22/24*Допущения!$B$7/12+X12*Допущения!$B$20 -> 208785.26 | Y19: =Y15+Y18-Y9*Допущения!$B$8*23/24*Допущения!$B$7/12+Y12*Допущения!$B$20 -> 218305.73 | Z19: Годовые подписчики и компании платят сразу за год.
A20: Расходы
A21: Хостинг Timeweb | B21: =Допущения!$B$29 -> 5300 | C21: =Допущения!$B$29 -> 5300 | D21: =Допущения!$B$29 -> 5300 | E21: =Допущения!$B$29 -> 5300 | F21: =Допущения!$B$29 -> 5300 | G21: =Допущения!$B$29 -> 5300 | H21: =Допущения!$B$29 -> 5300 | I21: =Допущения!$B$29 -> 5300 | ... Y21: =Допущения!$B$29 -> 5300
A22: Yandex.Cloud и ассистент | B22: =Допущения!$B$30+B10*Допущения!$B$26*Допущения!$B$27 -> 7000 | C22: =Допущения!$B$30+C10*Допущения!$B$26*Допущения!$B$27 -> 7000 | D22: =Допущения!$B$30+D10*Допущения!$B$26*Допущения!$B$27 -> 7048 | E22: =Допущения!$B$30+E10*Допущения!$B$26*Допущения!$B$27 -> 7103.332 | F22: =Допущения!$B$30+F10*Допущения!$B$26*Допущения!$B$27 -> 7153.3777 | G22: =Допущения!$B$30+G10*Допущения!$B$26*Допущения!$B$27 -> 7198.7429 | H22: =Допущения!$B$30+H10*Допущения!$B$26*Допущения!$B$27 -> 7239.9617 | I22: =Допущения!$B$30+I10*Допущения!$B$26*Допущения!$B$27 -> 7277.5053 | ... Y22: =Допущения!$B$30+Y10*Допущения!$B$26*Допущения!$B$27 -> 8152.2381 | Z22: Постоянный счёт плюс вопросы подписчиков: подписчики × вопросы × цена вопроса.
A23: Claude | B23: =Допущения!$B$31 -> 20000 | C23: =Допущения!$B$31 -> 20000 | D23: =Допущения!$B$31 -> 20000 | E23: =Допущения!$B$31 -> 20000 | F23: =Допущения!$B$31 -> 20000 | G23: =Допущения!$B$31 -> 20000 | H23: =Допущения!$B$31 -> 20000 | I23: =Допущения!$B$31 -> 20000 | ... Y23: =Допущения!$B$31 -> 20000
A24: API-ФНС | B24: =Допущения!$B$34 -> 8000 | C24: =Допущения!$B$34 -> 8000 | D24: =Допущения!$B$34 -> 8000 | E24: =Допущения!$B$34 -> 8000 | F24: =Допущения!$B$34 -> 8000 | G24: =Допущения!$B$34 -> 8000 | H24: =Допущения!$B$34 -> 8000 | I24: =Допущения!$B$34 -> 8000 | ... Y24: =Допущения!$B$34 -> 8000
A25: Онлайн-касса | B25: =Допущения!$B$35 -> 2500 | C25: =Допущения!$B$35 -> 2500 | D25: =Допущения!$B$35 -> 2500 | E25: =Допущения!$B$35 -> 2500 | F25: =Допущения!$B$35 -> 2500 | G25: =Допущения!$B$35 -> 2500 | H25: =Допущения!$B$35 -> 2500 | I25: =Допущения!$B$35 -> 2500 | ... Y25: =Допущения!$B$35 -> 2500
A26: Бухгалтерия | B26: =Допущения!$B$36 -> 7000 | C26: =Допущения!$B$36 -> 7000 | D26: =Допущения!$B$36 -> 7000 | E26: =Допущения!$B$36 -> 7000 | F26: =Допущения!$B$36 -> 7000 | G26: =Допущения!$B$36 -> 7000 | H26: =Допущения!$B$36 -> 7000 | I26: =Допущения!$B$36 -> 7000 | ... Y26: =Допущения!$B$36 -> 7000
A27: Аренда офиса | B27: =Допущения!$B$32 -> 1908 | C27: =Допущения!$B$32 -> 1908 | D27: =Допущения!$B$32 -> 1908 | E27: =Допущения!$B$32 -> 1908 | F27: =Допущения!$B$32 -> 1908 | G27: =Допущения!$B$32 -> 1908 | H27: =Допущения!$B$32 -> 1908 | I27: =Допущения!$B$32 -> 1908 | ... Y27: =Допущения!$B$32 -> 1908
A28: Обслуживание Pro | B28: =B13*Допущения!$B$24 -> 0 | C28: =C13*Допущения!$B$24 -> 0 | D28: =D13*Допущения!$B$24 -> 0 | E28: =E13*Допущения!$B$24 -> 800 | F28: =F13*Допущения!$B$24 -> 1586.6667 | G28: =G13*Допущения!$B$24 -> 2360.2222 | H28: =H13*Допущения!$B$24 -> 3120.8852 | I28: =I13*Допущения!$B$24 -> 3868.8704 | ... Y28: =Y13*Допущения!$B$24 -> 14274.591
A29: Юрист и товарный знак | B29: =Допущения!$B$37 -> 10000 | C29: =Допущения!$B$37 -> 10000 | D29: =Допущения!$B$37 -> 10000 | E29: =Допущения!$B$37 -> 10000 | F29: =Допущения!$B$37 -> 10000 | G29: =Допущения!$B$37 -> 10000 | H29: =Допущения!$B$37 -> 10000 | I29: =Допущения!$B$37 -> 10000 | ... Y29: =Допущения!$B$37 -> 10000
A30: Платная реклама | B30: =Допущения!$B$38 -> 30000 | C30: =Допущения!$B$38 -> 30000 | D30: =Допущения!$B$38 -> 30000 | E30: =Допущения!$B$38 -> 30000 | F30: =Допущения!$B$38 -> 30000 | G30: =Допущения!$B$38 -> 30000 | H30: =Допущения!$B$38 -> 30000 | I30: =Допущения!$B$38 -> 30000 | ... Y30: =Допущения!$B$38 -> 30000
A31: Прочее | B31: =Допущения!$B$39 -> 8000 | C31: =Допущения!$B$39 -> 8000 | D31: =Допущения!$B$39 -> 8000 | E31: =Допущения!$B$39 -> 8000 | F31: =Допущения!$B$39 -> 8000 | G31: =Допущения!$B$39 -> 8000 | H31: =Допущения!$B$39 -> 8000 | I31: =Допущения!$B$39 -> 8000 | ... Y31: =Допущения!$B$39 -> 8000
A32: Комиссия за платежи | B32: =B19*Допущения!$B$54 -> 0 | C32: =C19*Допущения!$B$54 -> 0 | D32: =D19*Допущения!$B$54 -> 138.402 | E32: =E19*Допущения!$B$54 -> 3286.0089 | F32: =F19*Допущения!$B$54 -> 3421.2024 | G32: =G19*Допущения!$B$54 -> 3544.5218 | H32: =H19*Допущения!$B$54 -> 3657.3298 | I32: =I19*Допущения!$B$54 -> 3760.8272 | ... Y32: =Y19*Допущения!$B$54 -> 6549.1719
A33: Возвраты по годовым подпискам | B33: =B18*Допущения!$B$10/2 -> 0 | C33: =C18*Допущения!$B$10/2 -> 0 | D33: =D18*Допущения!$B$10/2 -> 18.15 | E33: =E18*Допущения!$B$10/2 -> 34.03125 | F33: =F18*Допущения!$B$10/2 -> 45.375 | G33: =G18*Допущения!$B$10/2 -> 56.71875 | H33: =H18*Допущения!$B$10/2 -> 68.0625 | I33: =I18*Допущения!$B$10/2 -> 79.40625 | ... Y33: =Y18*Допущения!$B$10/2 -> 730.5375
A34: Зарплата гендиректора | B34: =Допущения!$B$41 -> 0 | C34: =Допущения!$B$41 -> 0 | D34: =Допущения!$B$41 -> 0 | E34: =Допущения!$B$41 -> 0 | F34: =Допущения!$B$41 -> 0 | G34: =Допущения!$B$41 -> 0 | H34: =Допущения!$B$41 -> 0 | I34: =Допущения!$B$41 -> 0 | ... Y34: =Допущения!$B$41 -> 0
A35: Команда на подряде | B35: =Допущения!$B$42 -> 0 | C35: =Допущения!$B$42 -> 0 | D35: =Допущения!$B$42 -> 0 | E35: =Допущения!$B$42 -> 0 | F35: =Допущения!$B$42 -> 0 | G35: =Допущения!$B$42 -> 0 | H35: =Допущения!$B$42 -> 0 | I35: =Допущения!$B$42 -> 0 | ... Y35: =Допущения!$B$42 -> 0
A36: Разработчик | B36: =IF(1<=Допущения!$B$43,0,IF(1<=Допущения!$B$45,Допущения!$B$44,Допущения!$B$46)) -> 0 | C36: =IF(2<=Допущения!$B$43,0,IF(2<=Допущения!$B$45,Допущения!$B$44,Допущения!$B$46)) -> 0 | D36: =IF(3<=Допущения!$B$43,0,IF(3<=Допущения!$B$45,Допущения!$B$44,Допущения!$B$46)) -> 0 | E36: =IF(4<=Допущения!$B$43,0,IF(4<=Допущения!$B$45,Допущения!$B$44,Допущения!$B$46)) -> 0 | F36: =IF(5<=Допущения!$B$43,0,IF(5<=Допущения!$B$45,Допущения!$B$44,Допущения!$B$46)) -> 0 | G36: =IF(6<=Допущения!$B$43,0,IF(6<=Допущения!$B$45,Допущения!$B$44,Допущения!$B$46)) -> 0 | H36: =IF(7<=Допущения!$B$43,0,IF(7<=Допущения!$B$45,Допущения!$B$44,Допущения!$B$46)) -> 50000 | I36: =IF(8<=Допущения!$B$43,0,IF(8<=Допущения!$B$45,Допущения!$B$44,Допущения!$B$46)) -> 50000 | J36: =IF(9<=Допущения!$B$43,0,IF(9<=Допущения!$B$45,Допущения!$B$44,Допущения!$B$46)) -> 50000 | K36: =IF(10<=Допущения!$B$43,0,IF(10<=Допущения!$B$45,Допущения!$B$44,Допущения!$B$46)) -> 50000 | L36: =IF(11<=Допущения!$B$43,0,IF(11<=Допущения!$B$45,Допущения!$B$44,Допущения!$B$46)) -> 50000 | M36: =IF(12<=Допущения!$B$43,0,IF(12<=Допущения!$B$45,Допущения!$B$44,Допущения!$B$46)) -> 50000 | N36: =IF(13<=Допущения!$B$43,0,IF(13<=Допущения!$B$45,Допущения!$B$44,Допущения!$B$46)) -> 100000 | O36: =IF(14<=Допущения!$B$43,0,IF(14<=Допущения!$B$45,Допущения!$B$44,Допущения!$B$46)) -> 100000 | P36: =IF(15<=Допущения!$B$43,0,IF(15<=Допущения!$B$45,Допущения!$B$44,Допущения!$B$46)) -> 100000 | Q36: =IF(16<=Допущения!$B$43,0,IF(16<=Допущения!$B$45,Допущения!$B$44,Допущения!$B$46)) -> 100000 | R36: =IF(17<=Допущения!$B$43,0,IF(17<=Допущения!$B$45,Допущения!$B$44,Допущения!$B$46)) -> 100000 | S36: =IF(18<=Допущения!$B$43,0,IF(18<=Допущения!$B$45,Допущения!$B$44,Допущения!$B$46)) -> 100000 | T36: =IF(19<=Допущения!$B$43,0,IF(19<=Допущения!$B$45,Допущения!$B$44,Допущения!$B$46)) -> 100000 | U36: =IF(20<=Допущения!$B$43,0,IF(20<=Допущения!$B$45,Допущения!$B$44,Допущения!$B$46)) -> 100000 | V36: =IF(21<=Допущения!$B$43,0,IF(21<=Допущения!$B$45,Допущения!$B$44,Допущения!$B$46)) -> 100000 | W36: =IF(22<=Допущения!$B$43,0,IF(22<=Допущения!$B$45,Допущения!$B$44,Допущения!$B$46)) -> 100000 | X36: =IF(23<=Допущения!$B$43,0,IF(23<=Допущения!$B$45,Допущения!$B$44,Допущения!$B$46)) -> 100000 | Y36: =IF(24<=Допущения!$B$43,0,IF(24<=Допущения!$B$45,Допущения!$B$44,Допущения!$B$46)) -> 100000 | Z36: Шесть месяцев без разработчика, шесть по 50 тыс, дальше по 100 тыс.
A37: Взнос на травматизм | B37: =Допущения!$B$52/12 -> 246.58333 | C37: =Допущения!$B$52/12 -> 246.58333 | D37: =Допущения!$B$52/12 -> 246.58333 | E37: =Допущения!$B$52/12 -> 246.58333 | F37: =Допущения!$B$52/12 -> 246.58333 | G37: =Допущения!$B$52/12 -> 246.58333 | H37: =Допущения!$B$52/12 -> 246.58333 | I37: =Допущения!$B$52/12 -> 246.58333 | ... Y37: =Допущения!$B$52/12 -> 246.58333
A38: Расходы всего | B38: =SUM(B21:B37) -> 99954.583 | C38: =SUM(C21:C37) -> 99954.583 | D38: =SUM(D21:D37) -> 100159.14 | E38: =SUM(E21:E37) -> 104177.96 | F38: =SUM(F21:F37) -> 105161.21 | G38: =SUM(G21:G37) -> 106114.79 | H38: =SUM(H21:H37) -> 157040.82 | I38: =SUM(I21:I37) -> 157941.19 | ... Y38: =SUM(Y21:Y37) -> 222661.12
A39: Налоги
A40: Доход с начала календарного года | B40: =SUM($B$17:B17) -> 0 | C40: =SUM($B$17:C17) -> 0 | D40: =SUM($B$17:D17) -> 3947.9 | E40: =SUM($E$17:E17) -> 16802.484 | F40: =SUM($E$17:F17) -> 45873.537 | G40: =SUM($E$17:G17) -> 86681.054 | H40: =SUM($E$17:H17) -> 138740.62 | I40: =SUM($E$17:I17) -> 201610.1 | J40: =SUM($E$17:J17) -> 275862.73 | K40: =SUM($E$17:K17) -> 361034.59 | L40: =SUM($E$17:L17) -> 456701.71 | ... Y40: =SUM($E$17:Y17) -> 2687462.5 | Z40: Старт в октябре, поэтому первый календарный год — три месяца.
...

Sheet Налоги и риски
A1: Налоги и риски
A3: Почему ООО на АУСН
A4: • | B4: Страховые взносы на АУСН — 0%. Остаётся только взнос на травматизм, 2 959 ₽ в год. На обычной УСН за гендиректора без зарплаты пришлось бы платить 8 128 ₽ в месяц: с 2026 года взносы с руководителя считаются от МРОТ, даже если зарплаты нет.
A5: • | B5: Плата за это — ставка 20% с прибыли вместо 15% и минимальный налог 3% от дохода вместо 1%, причём считается он за каждый месяц отдельно: убыточный месяц нельзя перекрыть прибыльным.
A6: • | B6: Пока мы в убытке, АУСН выгоднее обычной УСН при выручке до 4,73 млн ₽ в год; когда выйдем в прибыль — при прибыли до 1,89 млн ₽ в год. Выше — выгоднее перейти на УСН с начала следующего года.
A7: • | B7: НДС на АУСН нет до 60 млн ₽ дохода в год. На обычной УСН освобождение кончается на 20 млн ₽.
A9: Что нужно соблюдать, чтобы остаться на АУСН
A10: • | B10: Доход до 60 млн ₽ в год и не больше 5 человек. Спросить бухгалтера, считаются ли подрядчики, в том числе разработчик.
A11: • | B11: Счета только в банках из списка ФНС, выплаты только безналом, другие режимы совмещать нельзя, доля участника-юрлица — не больше 25%.
A12: • | B12: Деловую причину выбора режима лучше записать заранее: переход только ради нулевых взносов налоговая может оспорить.
A13: • | B13: Гендиректор без зарплаты при живой выручке — частый повод для вопросов банка.
A15: Разработчик на подряде: риск
A16: Подряд без взносов — законно и обычно. Но одинаковая сумма каждый месяц и единственный заказчик — признаки, по которым налоговая может признать отношения трудовыми. Снимает риск договор на конкретный результат, акт с перечнем сделанного на каждую сдачу и чек самозанятого на каждую выплату. Если подрядчик был нашим сотрудником в последние два года, самозанятым для нас он быть не может.
A17: Выплачено разработчику за 24 месяца | B17: =(Допущения!$B$44*6+Допущения!$B$46*12) -> 1500000 | C17: Шесть месяцев по первой ставке и двенадцать по второй.
A18: Взносы, если признают работником | B18: =(Допущения!$B$44*6+Допущения!$B$46*12)*Допущения!$B$53 -> 450000 | C18: 30% со всех выплат задним числом.
A19: Штраф 20% | B19: =(Допущения!$B$44*6+Допущения!$B$46*12)*Допущения!$B$53*0.2 -> 90000 | C19: П. 1 ст. 122 НК РФ.
A20: Итого при худшем исходе | B20: =(Допущения!$B$44*6+Допущения!$B$46*12)*Допущения!$B$53*1.2 -> 540000 | C20: Плюс пени.
A22: Что добавляет продажа людям
A23: • | B23: Чек на каждый платёж (54-ФЗ). Обычно его выбивает платёжный сервис — проверить в договоре; иначе нужна облачная касса.
A24: • | B24: Возврат: человек вправе отказаться в любой момент и получить деньги за неиспользованный срок, и оферта этого не отменит. Оформление доступа лицензией на базу данных может сузить возврат — вопрос юристу.
A25: • | B25: Персональные данные: уведомление Роскомнадзора, политика обработки и отдельное согласие на рассылку.
A26: • | B26: Реклама в каналах маркируется, и о ней отчитываются. Если это делает площадка — только по письменному поручению.
A27: • | B27: Товарный знак: пока он не зарегистрирован, название может занять кто угодно. Регистрация идёт около года.
A29: Источники ставок (проверено 23 сентября 2026)
A30: — ФЗ от 25.02.2022 № 17-ФЗ — АУСН: ставка 20%, минимальный налог 3% за месяц, нулевой тариф взносов, пределы 60 млн ₽ и 5 человек
A31: — ФЗ от 28.11.2025 № 425-ФЗ — взносы с руководителя от МРОТ (п. 1 ст. 421 НК РФ)
A32: — взнос на травматизм для АУСН на 2026 год — 2 959 ₽ в год
A33: — ст. 32 Закона РФ «О защите прав потребителей» — отказ от услуги и возврат
A34: — 54-ФЗ — касса при расчётах с людьми
A35: — Yandex AI Studio — 0,3 ₽ за 1000 токенов (gpt-oss-120b)
